ERROR:drinklogger:Exception on /accounts/login/ [POST]
Traceback (most recent call last):
  File "/home/felipe/Envs/drinklogger/local/lib/python2.7/site-packages/flask/app.py", line 1817, in wsgi_app
    response = self.full_dispatch_request()
  File "/home/felipe/Envs/drinklogger/local/lib/python2.7/site-packages/flask/app.py", line 1477, in full_dispatch_request
    rv = self.handle_user_exception(e)
  File "/home/felipe/Envs/drinklogger/local/lib/python2.7/site-packages/flask/app.py", line 1381, in handle_user_exception
    reraise(exc_type, exc_value, tb)
  File "/home/felipe/Envs/drinklogger/local/lib/python2.7/site-packages/flask/app.py", line 1475, in full_dispatch_request
    rv = self.dispatch_request()
  File "/home/felipe/Envs/drinklogger/local/lib/python2.7/site-packages/flask/app.py", line 1461, in dispatch_request
    return self.view_functions[rule.endpoint](**req.view_args)
  File "/home/felipe/Envs/drinklogger/src/flask-peewee/flask_peewee/auth.py", line 189, in login
    form.password.data,
  File "/home/felipe/Envs/drinklogger/src/flask-peewee/flask_peewee/auth.py", line 142, in authenticate
    user = active.where(self.User.username==username).get()
  File "/home/felipe/Envs/drinklogger/local/lib/python2.7/site-packages/peewee.py", line 2044, in get
    return clone.execute().next()
  File "/home/felipe/Envs/drinklogger/local/lib/python2.7/site-packages/peewee.py", line 2083, in execute
    self._qr = ResultWrapper(model_class, self._execute(), query_meta)
  File "/home/felipe/Envs/drinklogger/local/lib/python2.7/site-packages/peewee.py", line 1796, in _execute
    return self.database.execute_sql(sql, params, self.require_commit)
  File "/home/felipe/Envs/drinklogger/local/lib/python2.7/site-packages/peewee.py", line 2364, in execute_sql
    self.commit()
  File "/home/felipe/Envs/drinklogger/local/lib/python2.7/site-packages/peewee.py", line 2234, in __exit__
    reraise(new_type, new_type(*exc_value.args), traceback)
  File "/home/felipe/Envs/drinklogger/local/lib/python2.7/site-packages/peewee.py", line 2356, in execute_sql
    cursor.execute(sql, params or ())
ProgrammingError: relation "user" does not exist
LINE 1: ...ssword", t1."email", t1."active", t1."admin" FROM "user" AS ...
                                                             ^

